<?xml version="1.0"?>
<!--
  P3-AT robot with SICK LMS200 lidar.
  Uses official Pioneer 3-AT mesh files from amr-ros-config for accurate visual geometry.
  Adds base_footprint frame, LMS200 lidar link, and Gazebo simulation plugins.
-->
<robot name="p3at_lms" xmlns:xacro="http://www.ros.org/wiki/xacro">

  <xacro:property name="PI" value="3.1415926535897931"/>

  <!-- Mesh package path prefix -->
  <xacro:property name="mesh_prefix" value="package://p3at_lms_description/meshes/p3at_meshes"/>

  <!-- ======================== base_footprint ======================== -->
  <link name="base_footprint"/>

  <joint name="base_footprint_joint" type="fixed">
    <parent link="base_footprint"/>
    <child link="base_link"/>
    <origin xyz="0 0 0" rpy="0 0 0"/>
  </joint>

  <!-- ======================== Chassis (base_link) ======================== -->
  <link name="base_link">
    <inertial>
      <mass value="21.5"/>
      <origin xyz="-0.1 0 0.177"/>
      <inertia ixx="0.3338" ixy="0.0" ixz="0.0"
               iyy="0.4783" iyz="0.0"
               izz="0.3338"/>
    </inertial>
    <visual>
      <origin xyz="0 0 0.177" rpy="0 0 0"/>
      <geometry>
        <mesh filename="${mesh_prefix}/chassis.stl"/>
      </geometry>
      <material name="ChassisRed">
        <color rgba="0.851 0.0 0.0 1.0"/>
      </material>
    </visual>
    <collision>
      <origin xyz="0 0 0.177" rpy="0 0 0"/>
      <geometry>
        <!-- Slightly shorter than mesh to keep laser rays clear above -->
        <box size="0.50 0.40 0.16"/>
      </geometry>
    </collision>
  </link>
  <gazebo reference="base_link">
    <material>Gazebo/Red</material>
  </gazebo>

  <!-- ======================== Top plate ======================== -->
  <link name="top_plate">
    <inertial>
      <mass value="0.1"/>
      <origin xyz="-0.025 0 -0.223"/>
      <inertia ixx="0.001" ixy="0.0" ixz="0.0"
               iyy="0.001" iyz="0.0"
               izz="0.001"/>
    </inertial>
    <visual>
      <origin xyz="0 0 0" rpy="0 0 0"/>
      <geometry>
        <mesh filename="${mesh_prefix}/top.stl"/>
      </geometry>
      <material name="TopBlack">
        <color rgba="0.038 0.038 0.038 1.0"/>
      </material>
    </visual>
  </link>
  <gazebo reference="top_plate">
    <material>Gazebo/Black</material>
  </gazebo>

  <joint name="base_top_joint" type="fixed">
    <origin xyz="0.003 0 0.274" rpy="0 0 0"/>
    <parent link="base_link"/>
    <child link="top_plate"/>
  </joint>

  <!-- ======================== Front sonar ======================== -->
  <link name="front_sonar">
    <inertial>
      <mass value="0.1"/>
      <origin xyz="0 0 0"/>
      <inertia ixx="0.001" ixy="0.0" ixz="0.0"
               iyy="0.001" iyz="0.0"
               izz="0.001"/>
    </inertial>
    <visual>
      <origin xyz="0 0 0" rpy="0 0 0"/>
      <geometry>
        <mesh filename="${mesh_prefix}/front_sonar.stl"/>
      </geometry>
      <material name="SonarYellow">
        <color rgba="0.715 0.583 0.210 1.0"/>
      </material>
    </visual>
  </link>
  <gazebo reference="front_sonar">
    <material>Gazebo/Yellow</material>
  </gazebo>

  <joint name="base_front_joint" type="fixed">
    <origin xyz="0.193 0 0.25" rpy="0 0 0"/>
    <parent link="base_link"/>
    <child link="front_sonar"/>
  </joint>

  <!-- ======================== Back sonar ======================== -->
  <link name="back_sonar">
    <inertial>
      <mass value="0.1"/>
      <origin xyz="0 0 0"/>
      <inertia ixx="0.001" ixy="0.0" ixz="0.0"
               iyy="0.001" iyz="0.0"
               izz="0.001"/>
    </inertial>
    <visual>
      <origin xyz="0 0 0" rpy="0 0 0"/>
      <geometry>
        <mesh filename="${mesh_prefix}/back_sonar.stl"/>
      </geometry>
      <material name="SonarYellow">
        <color rgba="0.715 0.583 0.210 1.0"/>
      </material>
    </visual>
  </link>
  <gazebo reference="back_sonar">
    <material>Gazebo/Yellow</material>
  </gazebo>

  <joint name="base_back_joint" type="fixed">
    <origin xyz="-0.187 0 0.247" rpy="0 0 0"/>
    <parent link="base_link"/>
    <child link="back_sonar"/>
  </joint>

  <!-- ======================== Drive side macro ======================== -->
  <xacro:macro name="p3at_drive_side" params="side reflect">

    <!-- Front axle -->
    <link name="p3at_front_${side}_axle">
      <inertial>
        <mass value="0.1"/>
        <origin xyz="0 0 0"/>
        <inertia ixx="0.001" ixy="0.0" ixz="0.0"
                 iyy="0.001" iyz="0.0"
                 izz="0.001"/>
      </inertial>
      <visual>
        <origin xyz="0 0 0" rpy="0 0 0"/>
        <geometry>
          <mesh filename="${mesh_prefix}/axle.stl"/>
        </geometry>
        <material name="AxleGrey">
          <color rgba="0.5 0.5 0.5 1"/>
        </material>
      </visual>
    </link>
    <gazebo reference="p3at_front_${side}_axle">
      <material>Gazebo/Grey</material>
    </gazebo>

    <joint name="base_front_${side}_axle_joint" type="fixed">
      <origin xyz="0.135 ${reflect*0.156} 0.111" rpy="0 0 0"/>
      <parent link="base_link"/>
      <child link="p3at_front_${side}_axle"/>
    </joint>

    <!-- Front hub -->
    <link name="p3at_front_${side}_hub">
      <inertial>
        <mass value="0.1"/>
        <origin xyz="0 0 0"/>
        <inertia ixx="0.001" ixy="0.0" ixz="0.0"
                 iyy="0.001" iyz="0.0"
                 izz="0.001"/>
      </inertial>
      <visual>
        <origin xyz="0 0 0" rpy="0 0 0"/>
        <geometry>
          <mesh filename="${mesh_prefix}/${side}_hubcap.stl"/>
        </geometry>
        <material name="HubcapYellow">
          <color rgba="1.0 0.811 0.151 1.0"/>
        </material>
      </visual>
    </link>
    <gazebo reference="p3at_front_${side}_hub">
      <material>Gazebo/Yellow</material>
    </gazebo>

    <joint name="base_front_${side}_hub_joint" type="fixed">
      <origin xyz="0 ${reflect*0.041} 0" rpy="0 0 0"/>
      <parent link="p3at_front_${side}_axle"/>
      <child link="p3at_front_${side}_hub"/>
    </joint>

    <!-- Front wheel -->
    <link name="p3at_front_${side}_wheel">
      <inertial>
        <mass value="1.2"/>
        <origin xyz="0 0 0"/>
        <inertia ixx="0.012411765597" ixy="0" ixz="0"
                 iyy="0.015218160428" iyz="0"
                 izz="0.011763977943"/>
      </inertial>
      <visual>
        <origin xyz="0 0 0" rpy="0 0 0"/>
        <geometry>
          <mesh filename="${mesh_prefix}/wheel.stl"/>
        </geometry>
        <material name="WheelBlack">
          <color rgba="0.117 0.117 0.117 1"/>
        </material>
      </visual>
      <collision>
        <origin xyz="0 0 0" rpy="${-PI/2} 0 0"/>
        <geometry>
          <cylinder radius="0.111" length="0.075"/>
        </geometry>
      </collision>
    </link>
    <gazebo reference="p3at_front_${side}_wheel">
      <material>Gazebo/Black</material>
      <kp>1000000.0</kp>
      <kd>100.0</kd>
      <mu1>1.0</mu1>
      <mu2>1.0</mu2>
      <maxVel>1.0</maxVel>
      <minDepth>0.00</minDepth>
    </gazebo>

    <joint name="p3at_front_${side}_wheel_joint" type="continuous">
      <axis xyz="0 1 0"/>
      <limit effort="100" velocity="100"/>
      <joint_properties damping="0.7"/>
      <origin xyz="0 0 0" rpy="0 0 0"/>
      <parent link="p3at_front_${side}_hub"/>
      <child link="p3at_front_${side}_wheel"/>
    </joint>

    <!-- Back axle -->
    <link name="p3at_back_${side}_axle">
      <inertial>
        <mass value="0.1"/>
        <origin xyz="0 0 0"/>
        <inertia ixx="0.001" ixy="0.0" ixz="0.0"
                 iyy="0.001" iyz="0.0"
                 izz="0.001"/>
      </inertial>
      <visual>
        <origin xyz="0 0 0" rpy="0 0 0"/>
        <geometry>
          <mesh filename="${mesh_prefix}/axle.stl"/>
        </geometry>
        <material name="AxleGrey">
          <color rgba="0.5 0.5 0.5 1"/>
        </material>
      </visual>
    </link>
    <gazebo reference="p3at_back_${side}_axle">
      <material>Gazebo/Grey</material>
    </gazebo>

    <joint name="p3at_back_${side}_axle_joint" type="fixed">
      <origin xyz="-0.134 ${reflect*0.156} 0.111" rpy="0 0 0"/>
      <parent link="base_link"/>
      <child link="p3at_back_${side}_axle"/>
    </joint>

    <!-- Back hub -->
    <link name="p3at_back_${side}_hub">
      <inertial>
        <mass value="0.1"/>
        <origin xyz="0 0 0"/>
        <inertia ixx="0.001" ixy="0.0" ixz="0.0"
                 iyy="0.001" iyz="0.0"
                 izz="0.001"/>
      </inertial>
      <visual>
        <origin xyz="0 0 0" rpy="0 0 0"/>
        <geometry>
          <mesh filename="${mesh_prefix}/${side}_hubcap.stl"/>
        </geometry>
        <material name="HubcapYellow">
          <color rgba="1.0 0.811 0.151 1.0"/>
        </material>
      </visual>
    </link>
    <gazebo reference="p3at_back_${side}_hub">
      <material>Gazebo/Yellow</material>
    </gazebo>

    <joint name="p3at_back_${side}_hub_joint" type="fixed">
      <origin xyz="0 ${reflect*0.041} 0" rpy="0 0 0"/>
      <parent link="p3at_back_${side}_axle"/>
      <child link="p3at_back_${side}_hub"/>
    </joint>

    <!-- Back wheel -->
    <link name="p3at_back_${side}_wheel">
      <inertial>
        <mass value="1.2"/>
        <origin xyz="0 0 0"/>
        <inertia ixx="0.012411765597" ixy="0" ixz="0"
                 iyy="0.015218160428" iyz="0"
                 izz="0.011763977943"/>
      </inertial>
      <visual>
        <origin xyz="0 0 0" rpy="0 0 0"/>
        <geometry>
          <mesh filename="${mesh_prefix}/wheel.stl"/>
        </geometry>
        <material name="WheelBlack">
          <color rgba="0.117 0.117 0.117 1"/>
        </material>
      </visual>
      <collision>
        <origin xyz="0 0 0" rpy="${-PI/2} 0 0"/>
        <geometry>
          <cylinder radius="0.111" length="0.075"/>
        </geometry>
      </collision>
    </link>
    <gazebo reference="p3at_back_${side}_wheel">
      <material>Gazebo/Black</material>
      <kp>1000000.0</kp>
      <kd>100.0</kd>
      <mu1>1.0</mu1>
      <mu2>1.0</mu2>
      <maxVel>1.0</maxVel>
      <minDepth>0.00</minDepth>
    </gazebo>

    <joint name="p3at_back_${side}_wheel_joint" type="continuous">
      <axis xyz="0 1 0"/>
      <limit effort="100" velocity="100"/>
      <joint_properties damping="0.7"/>
      <origin xyz="0 0 0" rpy="0 0 0"/>
      <parent link="p3at_back_${side}_hub"/>
      <child link="p3at_back_${side}_wheel"/>
    </joint>

  </xacro:macro>

  <!-- Instantiate left and right drive sides -->
  <xacro:p3at_drive_side side="left"  reflect="1"/>
  <xacro:p3at_drive_side side="right" reflect="-1"/>

  <!-- ======================== SICK LMS200 Lidar ======================== -->
  <!--
    Mounted on top plate. The LMS200 is ~0.185m tall, sits on the top plate at z=0.274.
    laser frame origin at the scanner emission plane.
  -->
  <link name="laser">
    <inertial>
      <mass value="4.5"/>
      <origin xyz="0 0 0"/>
      <inertia ixx="0.01" ixy="0.0" ixz="0.0"
               iyy="0.01" iyz="0.0"
               izz="0.01"/>
    </inertial>
    <visual>
      <origin xyz="0 0 0" rpy="0 0 0"/>
      <geometry>
        <box size="0.156 0.155 0.185"/>
      </geometry>
      <material name="LMS200Blue">
        <color rgba="0.12 0.34 0.56 1.0"/>
      </material>
    </visual>
    <!-- No collision: prevents Gazebo ray sensor self-collision
         after fixed-joint link merging into base_link -->
  </link>
  <gazebo reference="laser">
    <material>Gazebo/Blue</material>
  </gazebo>

  <joint name="laser_joint" type="fixed">
    <parent link="base_link"/>
    <child link="laser"/>
    <!-- On top plate center, raised to emission plane -->
    <origin xyz="0.0 0.0 0.366" rpy="0 0 0"/>
  </joint>

  <!-- ======================== Gazebo Skid-Steer Drive Plugin ======================== -->
  <gazebo>
    <plugin name="skid_steer_drive" filename="libgazebo_ros_skid_steer_drive.so">
      <robotNamespace>/</robotNamespace>

      <leftFrontJoint>p3at_front_left_wheel_joint</leftFrontJoint>
      <rightFrontJoint>p3at_front_right_wheel_joint</rightFrontJoint>
      <leftRearJoint>p3at_back_left_wheel_joint</leftRearJoint>
      <rightRearJoint>p3at_back_right_wheel_joint</rightRearJoint>

      <wheelSeparation>0.4</wheelSeparation>
      <wheelDiameter>0.222</wheelDiameter>

      <torque>200</torque>
      <updateRate>50</updateRate>

      <commandTopic>cmd_vel</commandTopic>
      <odometryTopic>odom</odometryTopic>
      <odometryFrame>odom</odometryFrame>
      <robotBaseFrame>base_footprint</robotBaseFrame>

      <publishWheelTF>true</publishWheelTF>
      <publishTf>true</publishTf>
      <broadcastTF>true</broadcastTF>
      <publishWheelJointState>true</publishWheelJointState>
    </plugin>
  </gazebo>

  <!-- ======================== Gazebo LMS200 Lidar Sensor ======================== -->
  <gazebo reference="laser">
    <sensor type="ray" name="lms200">
      <pose>0 0 0 0 0 0</pose>
      <visualize>true</visualize>
      <update_rate>10</update_rate>
      <ray>
        <scan>
          <horizontal>
            <samples>361</samples>
            <resolution>1</resolution>
            <min_angle>-1.57079632679</min_angle>
            <max_angle> 1.57079632679</max_angle>
          </horizontal>
        </scan>
        <range>
          <min>0.05</min>
          <max>30.0</max>
          <resolution>0.01</resolution>
        </range>
        <noise>
          <type>gaussian</type>
          <mean>0.0</mean>
          <stddev>0.01</stddev>
        </noise>
      </ray>

      <plugin name="gazebo_ros_laser" filename="libgazebo_ros_laser.so">
        <topicName>scan</topicName>
        <frameName>laser</frameName>
      </plugin>
    </sensor>
  </gazebo>

</robot>
